<?xml version="1.0"?>
<robot xmlns:xacro="http://www.ros.org/wiki/xacro" name="spider_description">
  <xacro:include filename="$(find spider_description)/urdf/lidar.gazebo" />
  <xacro:include filename="$(find spider_description)/urdf/realsense2_camera.xacro" />

  <!-- <xacro:include filename="camera.xacro" /> -->
  <link name="dummy_base" />

  <joint name="dummy_base_to_base_link" type="fixed">
    <parent link="dummy_base" />
    <child link="base_link" />
    <origin xyz="0 0 0" rpy="0 0 0" />
  </joint>
  <link name="base_link">
    <inertial>
      <origin xyz="0.0513553543804905 -0.00355010292388771 0.0158371951293718" rpy="0 0 0" />
      <mass value="0.206587820695411" />
      <inertia ixx="9.18101041743378E-05" ixy="-1.10969157176021E-06" ixz="-2.07334737671984E-08" iyy="0.000621158029436724" iyz="3.17880975410804E-08" izz="0.000699601373790156" />
    </inertial>
    <visual>
      <origin xyz="0 0 0" rpy="0 0 0" />
      <geometry>
        <mesh filename="$(find spider_description)/meshes/visual/base_link.STL" />
      </geometry>
      <material name="">
        <color rgba="0.752941176470588 0.752941176470588 0.752941176470588 1" />
      </material>
    </visual>
    <collision>
      <origin xyz="0 0 0" rpy="0 0 0" />
      <geometry>
        <mesh filename="$(find spider_description)/meshes/collision/base_link.STL" />
      </geometry>
    </collision>
  </link>
  <link name="RL1_coxa">
    <inertial>
      <origin xyz="-0.00349163844394271 0.017230005966643 0.0244390511872048" rpy="0 0 0" />
      <mass value="0.0118214531865819" />
      <inertia ixx="1.54720054808557E-06" ixy="-3.57557713352019E-08" ixz="-4.02762646820984E-08" iyy="1.03828147386784E-06" iyz="-8.80078006023775E-10" izz="1.47258288978444E-06" />
    </inertial>
    <visual>
      <origin xyz="0 0 0" rpy="0 0 0" />
      <geometry>
        <mesh filename="$(find spider_description)/meshes/visual/RL1_coxa.STL" />
      </geometry>
      <material name="">
        <color rgba="0.752941176470588 0.752941176470588 0.752941176470588 1" />
      </material>
    </visual>
    <collision>
      <origin xyz="0 0 0" rpy="0 0 0" />
      <geometry>
        <mesh filename="$(find spider_description)/meshes/collision/RL1_coxa.STL" />
      </geometry>
    </collision>
  </link>
  <joint name="joint1_coxa" type="continuous">
    <origin xyz="0.14757063197026 -0.0470606865446389 0.00464999999999999" rpy="1.5707963267949 0 0.216963279781621" />
    <parent link="base_link" />
    <child link="RL1_coxa" />
    <axis xyz="0 1 0" />
  </joint>
  <link name="RL1_fumer">
    <inertial>
      <origin xyz="-0.0264233888332985 -2.08166817117217E-17 -0.00234030420177739" rpy="0 0 0" />
      <mass value="0.00732061922605987" />
      <inertia ixx="1.66034801156123E-06" ixy="-8.99972506457694E-22" ixz="-1.499875031394E-09" iyy="3.3348950865199E-06" iyz="1.31159825877939E-21" izz="1.8515397312667E-06" />
    </inertial>
    <visual>
      <origin xyz="0 0 0" rpy="0 0 0" />
      <geometry>
        <mesh filename="$(find spider_description)/meshes/visual/RL1_fumer.STL" />
      </geometry>
      <material name="">
        <color rgba="1 1 1 1" />
      </material>
    </visual>
    <collision>
      <origin xyz="0 0 0" rpy="0 0 0" />
      <geometry>
        <mesh filename="$(find spider_description)/meshes/collision/RL1_fumer.STL" />
      </geometry>
    </collision>
  </link>
  <joint name="joint1_fumer" type="continuous">
    <origin xyz="-0.00591979008225604 0.0221000000000001 0.0268552804003611" rpy="-1.98602850950399 1.00791673675336 1.213911849099" />
    <parent link="RL1_coxa" />
    <child link="RL1_fumer" />
    <axis xyz="0 0 1" />
  </joint>
  <link name="RL1_tibia">
    <inertial>
      <origin xyz="0.00260154713513185 -0.0130975375024425 0.00072742607377918" rpy="0 0 0" />
      <mass value="0.013123891605465" />
      <inertia ixx="4.2299662226924E-06" ixy="1.19149413513681E-07" ixz="-1.17548988409948E-08" iyy="7.82194147309099E-07" iyz="-2.83284559215829E-07" izz="4.42455942176531E-06" />
    </inertial>
    <visual>
      <origin xyz="0 0 0" rpy="0 0 0" />
      <geometry>
        <mesh filename="$(find spider_description)/meshes/visual/RL1_tibia.STL" />
      </geometry>
      <material name="">
        <color rgba="0.752941176470588 0.752941176470588 0.752941176470588 1" />
      </material>
    </visual>
    <collision>
      <origin xyz="0 0 0" rpy="0 0 0" />
      <geometry>
        <mesh filename="$(find spider_description)/meshes/collision/RL1_tibia.STL" />
      </geometry>
    </collision>
  </link>
  <joint name="joint1_tibia" type="continuous">
    <origin xyz="-0.055 0 0" rpy="3.14159265358979 1.35383304701328 0.527393489709591" />
    <parent link="RL1_fumer" />
    <child link="RL1_tibia" />
    <axis xyz="0.976555650922224 0 0.215265093900221" />
  </joint>
  <link name="RL2_coxa">
    <inertial>
      <origin xyz="-0.00137410211994941 0.017230005966643 0.024648947347057" rpy="0 0 0" />
      <mass value="0.0118214531865819" />
      <inertia ixx="1.53973619894474E-06" ixy="-3.56987341340022E-08" ixz="-4.6080725279413E-08" iyy="1.03828147386784E-06" iyz="2.2022947808455E-09" izz="1.48004723892527E-06" />
    </inertial>
    <visual>
      <origin xyz="0 0 0" rpy="0 0 0" />
      <geometry>
        <mesh filename="$(find spider_description)/meshes/visual/RL2_coxa.STL" />
      </geometry>
      <material name="">
        <color rgba="0.752941176470588 0.752941176470588 0.752941176470588 1" />
      </material>
    </visual>
    <collision>
      <origin xyz="0 0 0" rpy="0 0 0" />
      <geometry>
        <mesh filename="$(find spider_description)/meshes/collision/RL2_coxa.STL" />
      </geometry>
    </collision>
  </link>
  <joint name="joint2_coxa" type="continuous">
    <origin xyz="0.0870706319702602 -0.0470606865446389 0.00464999999999997" rpy="1.5707963267949 0 0.130741621531395" />
    <parent link="base_link" />
    <child link="RL2_coxa" />
    <axis xyz="0 1 0" />
  </joint>
  <link name="RL2_fumer">
    <inertial>
      <origin xyz="-0.0264233888332987 6.24500451351651E-17 0.0581596957982228" rpy="0 0 0" />
      <mass value="0.00732061922605988" />
      <inertia ixx="1.66034801156124E-06" ixy="6.88214269644119E-22" ixz="-1.49987503139386E-09" iyy="3.33489508651991E-06" iyz="3.43796942092352E-22" izz="1.85153973126671E-06" />
    </inertial>
    <visual>
      <origin xyz="0 0 0" rpy="0 0 0" />
      <geometry>
        <mesh filename="$(find spider_description)/meshes/visual/RL2_fumer.STL" />
      </geometry>
      <material name="">
        <color rgba="1 1 1 1" />
      </material>
    </visual>
    <collision>
      <origin xyz="0 0 0" rpy="0 0 0" />
      <geometry>
        <mesh filename="$(find spider_description)/meshes/collision/RL2_fumer.STL" />
      </geometry>
    </collision>
  </link>
  <joint name="joint2_fumer" type="continuous">
    <origin xyz="0.0563985011948722 0.0221000000000001 0.0351526537116618" rpy="-1.82795682053227 1.0325993659782 1.3487143343647" />
    <parent link="RL2_coxa" />
    <child link="RL2_fumer" />
    <axis xyz="0 0 1" />
  </joint>
  <link name="RL2_tibia">
    <inertial>
      <origin xyz="-0.0562495143524853 -0.0130839593275274 -0.00677615060162512" rpy="0 0 0" />
      <mass value="0.013123891605465" />
      <inertia ixx="4.23019150195768E-06" ixy="7.84253861591576E-08" ixz="1.01977946227711E-09" iyy="7.65338483748999E-07" iyz="-1.6371410447347E-07" izz="4.44118980606013E-06" />
    </inertial>
    <visual>
      <origin xyz="0 0 0" rpy="0 0 0" />
      <geometry>
        <mesh filename="$(find spider_description)/meshes/visual/RL2_tibia.STL" />
      </geometry>
      <material name="">
        <color rgba="0.752941176470588 0.752941176470588 0.752941176470588 1" />
      </material>
    </visual>
    <collision>
      <origin xyz="0 0 0" rpy="0 0 0" />
      <geometry>
        <mesh filename="$(find spider_description)/meshes/collision/RL2_tibia.STL" />
      </geometry>
    </collision>
  </link>
  <joint name="joint2_tibia" type="continuous">
    <origin xyz="-0.055 0 0" rpy="-3.14159265358979 1.4400547052635 0.491910301591065" />
    <parent link="RL2_fumer" />
    <child link="RL2_tibia" />
    <axis xyz="0.991465481571485 0 0.130369470552824" />
  </joint>
  <link name="RL3_coxa">
    <inertial>
      <origin xyz="0.00349358134474833 0.017230005966643 0.0244387735236787" rpy="0 0 0" />
      <mass value="0.0118214531865818" />
      <inertia ixx="1.51968642178633E-06" ixy="-3.45709794269535E-08" ixz="-5.40202742068447E-08" iyy="1.03828147386784E-06" iyz="9.17044723735254E-09" izz="1.50009701608367E-06" />
    </inertial>
    <visual>
      <origin xyz="0 0 0" rpy="0 0 0" />
      <geometry>
        <mesh filename="$(find spider_description)/meshes/visual/RL3_coxa.STL" />
      </geometry>
      <material name="">
        <color rgba="0.752941176470588 0.752941176470588 0.752941176470588 1" />
      </material>
    </visual>
    <collision>
      <origin xyz="0 0 0" rpy="0 0 0" />
      <geometry>
        <mesh filename="$(find spider_description)/meshes/collision/RL3_coxa.STL" />
      </geometry>
    </collision>
  </link>
  <joint name="joint3_coxa" type="continuous">
    <origin xyz="0.0265706319702601 -0.0470606865446388 0.00464999999999998" rpy="1.5707963267949 0 -0.0669380319605713" />
    <parent link="base_link" />
    <child link="RL3_coxa" />
    <axis xyz="0 1 0" />
  </joint>
  <link name="RL3_fumer">
    <inertial>
      <origin xyz="-0.0264233888332993 -3.12250225675825E-16 0.118659695798224" rpy="0 0 0" />
      <mass value="0.00732061922605988" />
      <inertia ixx="1.66034801156124E-06" ixy="-5.29395592033938E-23" ixz="-1.49987503139564E-09" iyy="3.33489508651991E-06" iyz="-7.52681582497153E-23" izz="1.85153973126671E-06" />
    </inertial>
    <visual>
      <origin xyz="0 0 0" rpy="0 0 0" />
      <geometry>
        <mesh filename="$(find spider_description)/meshes/visual/RL3_fumer.STL" />
      </geometry>
      <material name="">
        <color rgba="1 1 1 1" />
      </material>
    </visual>
    <collision>
      <origin xyz="0 0 0" rpy="0 0 0" />
      <geometry>
        <mesh filename="$(find spider_description)/meshes/collision/RL3_fumer.STL" />
      </geometry>
    </collision>
  </link>
  <joint name="joint3_fumer" type="continuous">
    <origin xyz="0.122568440358491 0.0221000000000001 0.0193449587253901" rpy="-1.43751480215154 1.04333153380391 1.6861356410289" />
    <parent link="RL3_coxa" />
    <child link="RL3_fumer" />
    <axis xyz="0 0 1" />
  </joint>
  <link name="RL3_tibia">
    <inertial>
      <origin xyz="-0.118005534421714 -0.0130894519462948 0.00839605198202772" rpy="0 0 0" />
      <mass value="0.013123891605465" />
      <inertia ixx="4.23878065273637E-06" ixy="4.20082265127764E-08" ixz="4.18757931219034E-08" iyy="7.69154461537199E-07" iyz="-2.12494160023349E-07" izz="4.42878467749323E-06" />
    </inertial>
    <visual>
      <origin xyz="0 0 0" rpy="0 0 0" />
      <geometry>
        <mesh filename="$(find spider_description)/meshes/visual/RL3_tibia.STL" />
      </geometry>
      <material name="">
        <color rgba="0.752941176470588 0.752941176470588 0.752941176470588 1" />
      </material>
    </visual>
    <collision>
      <origin xyz="0 0 0" rpy="0 0 0" />
      <geometry>
        <mesh filename="$(find spider_description)/meshes/collision/RL3_tibia.STL" />
      </geometry>
    </collision>
  </link>
  <joint name="joint3_tibia" type="continuous">
    <origin xyz="-0.055 0 0" rpy="0 1.50385829483433 -2.63968666156776" />
    <parent link="RL3_fumer" />
    <child link="RL3_tibia" />
    <axis xyz="0.997760486341758 0 -0.0668880549504799" />
  </joint>
  <link name="RL4_coxa">
    <inertial>
      <origin xyz="0.000221643372700024 0.0172339889705058 0.0247738629223978" rpy="0 0 0" />
      <mass value="0.011831113051677" />
      <inertia ixx="1.51589381883954E-06" ixy="3.36933681099745E-08" ixz="5.44221588671393E-08" iyy="1.03946591481982E-06" iyz="1.04055511028782E-08" izz="1.50574484630922E-06" />
    </inertial>
    <visual>
      <origin xyz="0 0 0" rpy="0 0 0" />
      <geometry>
        <mesh filename="$(find spider_description)/meshes/visual/RL4_coxa.STL" />
      </geometry>
      <material name="">
        <color rgba="0.752941176470588 0.752941176470588 0.752941176470588 1" />
      </material>
    </visual>
    <collision>
      <origin xyz="0 0 0" rpy="0 0 0" />
      <geometry>
        <mesh filename="$(find spider_description)/meshes/collision/RL4_coxa.STL" />
      </geometry>
    </collision>
  </link>
  <joint name="joint4_coxa" type="continuous">
    <origin xyz="-0.0339293680297398 -0.0470606865446389 0.00465" rpy="1.5707963267949 0 0.105302517917499" />
    <parent link="base_link" />
    <child link="RL4_coxa" />
    <axis xyz="0 1 0" />
  </joint>
  <link name="RL4_fumer">
    <inertial>
      <origin xyz="-0.0264233888332989 6.93889390390723E-18 -0.176940304201777" rpy="0 0 0" />
      <mass value="0.00732061922605987" />
      <inertia ixx="1.66034801156123E-06" ixy="5.29395592033938E-22" ixz="-1.49987503139487E-09" iyy="3.3348950865199E-06" iyz="1.10684466970948E-22" izz="1.85153973126671E-06" />
    </inertial>
    <visual>
      <origin xyz="0 0 0" rpy="0 0 0" />
      <geometry>
        <mesh filename="$(find spider_description)/meshes/visual/RL4_fumer.STL" />
      </geometry>
      <material name="">
        <color rgba="1 1 1 1" />
      </material>
    </visual>
    <collision>
      <origin xyz="0 0 0" rpy="0 0 0" />
      <geometry>
        <mesh filename="$(find spider_description)/meshes/collision/RL4_fumer.STL" />
      </geometry>
    </collision>
  </link>
  <joint name="joint4_fumer" type="continuous">
    <origin xyz="0.177604166796266 0.0221000000000001 0.0464247771842149" rpy="1.3624761407313 1.03768167086435 1.39071609018261" />
    <parent link="RL4_coxa" />
    <child link="RL4_fumer" />
    <axis xyz="0 0 1" />
  </joint>
  <link name="RL4_tibia">
    <inertial>
      <origin xyz="-0.175875204861774 -0.0124119057129758 -0.0227969872954879" rpy="0 0 0" />
      <mass value="0.013123891605465" />
      <inertia ixx="4.23942335897909E-06" ixy="1.02033754178209E-07" ixz="-4.08467258993433E-09" iyy="1.36774622886964E-06" iyz="-1.36758688607792E-06" izz="3.8295502039181E-06" />
    </inertial>
    <visual>
      <origin xyz="0 0 0" rpy="0 0 0" />
      <geometry>
        <mesh filename="$(find spider_description)/meshes/visual/RL4_tibia.STL" />
      </geometry>
      <material name="">
        <color rgba="0.752941176470588 0.752941176470588 0.752941176470588 1" />
      </material>
    </visual>
    <collision>
      <origin xyz="0 0 0" rpy="0 0 0" />
      <geometry>
        <mesh filename="$(find spider_description)/meshes/collision/RL4_tibia.STL" />
      </geometry>
    </collision>
  </link>
  <joint name="joint4_tibia" type="continuous">
    <origin xyz="-0.055 0 0" rpy="0 -1.4654938088774 -0.864064197891256" />
    <parent link="RL4_fumer" />
    <child link="RL4_tibia" />
    <axis xyz="0.994460811195995 0 0.105108015847522" />
  </joint>
  <link name="LL1_coxa">
    <inertial>
      <origin xyz="0.0170998828634738 0.0172339889705059 -0.0179272813314759" rpy="0 0 0" />
      <mass value="0.011831113051677" />
      <inertia ixx="1.45656947113537E-06" ixy="-1.69226594240046E-08" ixz="6.66890699376832E-09" iyy="1.03946591481982E-06" iyz="-3.09377139809669E-08" izz="1.56506919401288E-06" />
    </inertial>
    <visual>
      <origin xyz="0 0 0" rpy="0 0 0" />
      <geometry>
        <mesh filename="$(find spider_description)/meshes/visual/LL1_coxa.STL" />
      </geometry>
      <material name="">
        <color rgba="0.752941176470588 0.752941176470588 0.752941176470588 1" />
      </material>
    </visual>
    <collision>
      <origin xyz="0 0 0" rpy="0 0 0" />
      <geometry>
        <mesh filename="$(find spider_description)/meshes/collision/LL1_coxa.STL" />
      </geometry>
    </collision>
  </link>
  <joint name="joint5_coxa" type="continuous">
    <origin xyz="0.14757063197026 0.0399393134553611 0.00465000000000003" rpy="1.5707963267949 0 0.876029873391859" />
    <parent link="base_link" />
    <child link="LL1_coxa" />
    <axis xyz="0 1 0" />
  </joint>
  <link name="LL1_fumer">
    <inertial>
      <origin xyz="-0.0264233888332986 0 0.00455969579822271" rpy="0 0 0" />
      <mass value="0.00732061922605989" />
      <inertia ixx="1.66034801156124E-06" ixy="-2.64697796016969E-22" ixz="-1.49987503139553E-09" iyy="3.33489508651991E-06" iyz="1.79363776074467E-21" izz="1.85153973126671E-06" />
    </inertial>
    <visual>
      <origin xyz="0 0 0" rpy="0 0 0" />
      <geometry>
        <mesh filename="$(find spider_description)/meshes/visual/LL1_fumer.STL" />
      </geometry>
      <material name="">
        <color rgba="1 1 1 1" />
      </material>
    </visual>
    <collision>
      <origin xyz="0 0 0" rpy="0 0 0" />
      <geometry>
        <mesh filename="$(find spider_description)/meshes/collision/LL1_fumer.STL" />
      </geometry>
    </collision>
  </link>
  <joint name="joint5_fumer" type="continuous">
    <origin xyz="0.0211255891188233 0.0221 -0.0176056662578457" rpy="-2.74678119264294 -0.58768354984189 2.49709435666674" />
    <parent link="LL1_coxa" />
    <child link="LL1_fumer" />
    <axis xyz="0 0 1" />
  </joint>
  <link name="LL1_tibia">
    <inertial>
      <origin xyz="-0.00279894261734365 -0.0130976424430121 -0.00313843380108422" rpy="0 0 0" />
      <mass value="0.013123891605465" />
      <inertia ixx="4.36602526509336E-06" ixy="-2.59110649699593E-07" ixz="-7.85274951562137E-08" iyy="7.97432607148881E-07" iyz="2.87128236854985E-07" izz="4.27326191952455E-06" />
    </inertial>
    <visual>
      <origin xyz="0 0 0" rpy="0 0 0" />
      <geometry>
        <mesh filename="$(find spider_description)/meshes/visual/LL1_tibia.STL" />
      </geometry>
      <material name="">
        <color rgba="0.752941176470588 0.752941176470588 0.752941176470588 1" />
      </material>
    </visual>
    <collision>
      <origin xyz="0 0 0" rpy="0 0 0" />
      <geometry>
        <mesh filename="$(find spider_description)/meshes/collision/LL1_tibia.STL" />
      </geometry>
    </collision>
  </link>
  <joint name="joint5_tibia" type="continuous">
    <origin xyz="-0.0549999999999999 0 0" rpy="3.14159265358979 0.694766453403041 2.59196218761899" />
    <parent link="LL1_fumer" />
    <child link="LL1_tibia" />
    <axis xyz="0.640206045739847 0 0.768203240684487" />
  </joint>
  <link name="LL2_coxa">
    <inertial>
      <origin xyz="0.0127223107624808 0.0169176334399643 -0.0226841712591478" rpy="0 0 0" />
      <mass value="0.011831113051677" />
      <inertia ixx="1.56088112402009E-06" ixy="-2.81601853556498E-08" ixz="2.19396104805271E-08" iyy="1.03946591481982E-06" iyz="-2.12255249861135E-08" izz="1.4607575411285E-06" />
    </inertial>
    <visual>
      <origin xyz="0 0 0" rpy="0 0 0" />
      <geometry>
        <mesh filename="$(find spider_description)/meshes/visual/LL2_coxa.STL" />
      </geometry>
      <material name="">
        <color rgba="0.752941176470588 0.752941176470588 0.752941176470588 1" />
      </material>
    </visual>
    <collision>
      <origin xyz="0 0 0" rpy="0 0 0" />
      <geometry>
        <mesh filename="$(find spider_description)/meshes/collision/LL2_coxa.STL" />
      </geometry>
    </collision>
  </link>
  <joint name="joint6_coxa" type="continuous">
    <origin xyz="0.0870706319702601 0.0399393134553608 0.00464999999999998" rpy="1.5707963267949 0 0.840128894013488" />
    <parent link="base_link" />
    <child link="LL2_coxa" />
    <axis xyz="0 1 0" />
  </joint>
  <link name="LL2_fumer">
    <inertial>
      <origin xyz="-0.0264233888332989 3.46944695195361E-17 0.0725596957982222" rpy="0 0 0" />
      <mass value="0.00732061922605988" />
      <inertia ixx="1.66034801156123E-06" ixy="-1.11173074327127E-21" ixz="-1.49987503139377E-09" iyy="3.33489508651991E-06" iyz="-3.43796942092352E-22" izz="1.85153973126671E-06" />
    </inertial>
    <visual>
      <origin xyz="0 0 0" rpy="0 0 0" />
      <geometry>
        <mesh filename="$(find spider_description)/meshes/visual/LL2_fumer.STL" />
      </geometry>
      <material name="">
        <color rgba="1 1 1 1" />
      </material>
    </visual>
    <collision>
      <origin xyz="0 0 0" rpy="0 0 0" />
      <geometry>
        <mesh filename="$(find spider_description)/meshes/collision/LL2_fumer.STL" />
      </geometry>
    </collision>
  </link>
  <joint name="joint6_fumer" type="continuous">
    <origin xyz="0.0608557453435872 0.0221 0.026703525210662" rpy="-2.72035311532009 -0.616222550074482 2.48212725475599" />
    <parent link="LL2_coxa" />
    <child link="LL2_fumer" />
    <axis xyz="0 0 1" />
  </joint>
  <link name="LL2_tibia">
    <inertial>
      <origin xyz="-0.01480952139402 -0.013098396107006 -0.0165422174946064" rpy="0 0 0" />
      <mass value="0.013123891605465" />
      <inertia ixx="4.36428688191597E-06" ixy="-2.1723438599018E-07" ixz="-8.58851441227647E-08" iyy="7.89056082804284E-07" iyz="2.68586343447735E-07" izz="4.28337682704655E-06" />
    </inertial>
    <visual>
      <origin xyz="0 0 0" rpy="0 0 0" />
      <geometry>
        <mesh filename="$(find spider_description)/meshes/visual/LL2_tibia.STL" />
      </geometry>
      <material name="">
        <color rgba="0.752941176470588 0.752941176470588 0.752941176470588 1" />
      </material>
    </visual>
    <collision>
      <origin xyz="0 0 0" rpy="0 0 0" />
      <geometry>
        <mesh filename="$(find spider_description)/meshes/collision/LL2_tibia.STL" />
      </geometry>
    </collision>
  </link>
  <joint name="joint6_tibia" type="continuous">
    <origin xyz="-0.0549999999999999 0 0.0500000000000001" rpy="3.14159265358979 0.730667432781409 2.60353309806751" />
    <parent link="LL2_fumer" />
    <child link="LL2_tibia" />
    <axis xyz="0.667366840256722 0 0.744729145747471" />
  </joint>
  <link name="LL3_coxa">
    <inertial>
      <origin xyz="0.0139602506872404 0.0172339889705058 -0.0204671642059132" rpy="0 0 0" />
      <mass value="0.011831113051677" />
      <inertia ixx="1.46157119792145E-06" ixy="-2.17239801391936E-08" ixz="2.37095554539394E-08" iyy="1.03946591481982E-06" iyz="-2.7777459121755E-08" izz="1.56006746722729E-06" />
    </inertial>
    <visual>
      <origin xyz="0 0 0" rpy="0 0 0" />
      <geometry>
        <mesh filename="$(find spider_description)/meshes/visual/LL3_coxa.STL" />
      </geometry>
      <material name="">
        <color rgba="0.752941176470588 0.752941176470588 0.752941176470588 1" />
      </material>
    </visual>
    <collision>
      <origin xyz="0 0 0" rpy="0 0 0" />
      <geometry>
        <mesh filename="$(find spider_description)/meshes/collision/LL3_coxa.STL" />
      </geometry>
    </collision>
  </link>
  <joint name="joint7_coxa" type="continuous">
    <origin xyz="0.0265706319702602 0.0399393134553611 0.00464999999999998" rpy="1.5707963267949 0 0.712846787592376" />
    <parent link="base_link" />
    <child link="LL3_coxa" />
    <axis xyz="0 1 0" />
  </joint>
  <link name="LL3_fumer">
    <inertial>
      <origin xyz="-0.0264233888332988 1.66533453693773E-16 0.125559695798222" rpy="0 0 0" />
      <mass value="0.00732061922605986" />
      <inertia ixx="1.66034801156123E-06" ixy="6.88214269644119E-22" ixz="-1.49987503139546E-09" iyy="3.3348950865199E-06" iyz="1.01789636639699E-22" izz="1.85153973126671E-06" />
    </inertial>
    <visual>
      <origin xyz="0 0 0" rpy="0 0 0" />
      <geometry>
        <mesh filename="$(find spider_description)/meshes/visual/LL3_fumer.STL" />
      </geometry>
      <material name="">
        <color rgba="1 1 1 1" />
      </material>
    </visual>
    <collision>
      <origin xyz="0 0 0" rpy="0 0 0" />
      <geometry>
        <mesh filename="$(find spider_description)/meshes/collision/LL3_fumer.STL" />
      </geometry>
    </collision>
  </link>
  <joint name="joint7_fumer" type="continuous">
    <origin xyz="0.10952160956792 0.0221 0.0583289553965433" rpy="-2.61722554755421 -0.71438242643614 2.41835522432309" />
    <parent link="LL3_coxa" />
    <child link="LL3_fumer" />
    <axis xyz="0 0 1" />
  </joint>
  <link name="LL3_tibia">
    <inertial>
      <origin xyz="-0.094631241235736 -0.00999543048455966 -0.0821821673541989" rpy="0 0 0" />
      <mass value="0.021123795973342" />
      <inertia ixx="4.99508664772741E-06" ixy="-1.3939361777078E-07" ixz="-2.6733864336624E-07" iyy="1.32635282258011E-06" iyz="1.78140065284283E-07" izz="5.0128656775895E-06" />
    </inertial>
    <visual>
      <origin xyz="0 0 0" rpy="0 0 0" />
      <geometry>
        <mesh filename="$(find spider_description)/meshes/visual/LL3_tibia.STL" />
      </geometry>
      <material name="">
        <color rgba="0.752941176470588 0.752941176470588 0.752941176470588 1" />
      </material>
    </visual>
    <collision>
      <origin xyz="0 0 0" rpy="0 0 0" />
      <geometry>
        <mesh filename="$(find spider_description)/meshes/collision/LL3_tibia.STL" />
      </geometry>
    </collision>
  </link>
  <joint name="joint7_tibia" type="continuous">
    <origin xyz="-0.0549999999999999 0 0" rpy="3.14159265358979 0.857949539202522 2.63388766827357" />
    <parent link="LL3_fumer" />
    <child link="LL3_tibia" />
    <axis xyz="0.756503173249345 0 0.65399002199091" />
  </joint>
  <link name="LL4_coxa">
    <inertial>
      <origin xyz="0.000589847633677063 0.017230005966643 -0.0246801710229706" rpy="0 0 0" />
      <mass value="0.0118214531865818" />
      <inertia ixx="1.53674766199004E-06" ixy="3.56106840430809E-08" ixz="-4.7884074095185E-08" iyy="1.03828147386784E-06" iyz="-3.33600105752003E-09" izz="1.48303577587997E-06" />
    </inertial>
    <visual>
      <origin xyz="0 0 0" rpy="0 0 0" />
      <geometry>
        <mesh filename="$(find spider_description)/meshes/visual/LL4_coxa.STL" />
      </geometry>
      <material name="">
        <color rgba="0.752941176470588 0.752941176470588 0.752941176470588 1" />
      </material>
    </visual>
    <collision>
      <origin xyz="0 0 0" rpy="0 0 0" />
      <geometry>
        <mesh filename="$(find spider_description)/meshes/collision/LL4_coxa.STL" />
      </geometry>
    </collision>
  </link>
  <joint name="joint8_coxa" type="continuous">
    <origin xyz="-0.0339293680297398 0.039939313455361 0.00464999999999999" rpy="1.5707963267949 0 0.0989474826412098" />
    <parent link="base_link" />
    <child link="LL4_coxa" />
    <axis xyz="0 1 0" />
  </joint>
  <link name="LL4_fumer">
    <inertial>
      <origin xyz="-0.0264233888332985 1.38777878078145E-17 -0.183840304201777" rpy="0 0 0" />
      <mass value="0.00732061922605988" />
      <inertia ixx="1.66034801156124E-06" ixy="-4.76456032830544E-22" ixz="-1.49987503139489E-09" iyy="3.33489508651991E-06" iyz="-1.02981347516547E-22" izz="1.85153973126671E-06" />
    </inertial>
    <visual>
      <origin xyz="0 0 0" rpy="0 0 0" />
      <geometry>
        <mesh filename="$(find spider_description)/meshes/visual/LL4_fumer.STL" />
      </geometry>
      <material name="">
        <color rgba="1 1 1 1" />
      </material>
    </visual>
    <collision>
      <origin xyz="0 0 0" rpy="0 0 0" />
      <geometry>
        <mesh filename="$(find spider_description)/meshes/collision/LL4_fumer.STL" />
      </geometry>
    </collision>
  </link>
  <joint name="joint8_fumer" type="continuous">
    <origin xyz="0.18332884514746 0.0221 -0.0094358114064664" rpy="1.37480179147324 -1.03878671960298 1.74025786812046" />
    <parent link="LL4_coxa" />
    <child link="LL4_fumer" />
    <axis xyz="0 0 1" />
  </joint>
  <link name="LL4_tibia">
    <inertial>
      <origin xyz="-0.180394375659539 -0.0130639420354095 -0.0372472679266889" rpy="0 0 0" />
      <mass value="0.013123891605465" />
      <inertia ixx="4.2246722620473E-06" ixy="-1.76333803207243E-07" ixz="9.44080756640397E-09" iyy="8.5838893710165E-07" iyz="5.7833463564039E-07" izz="4.35365859261787E-06" />
    </inertial>
    <visual>
      <origin xyz="0 0 0" rpy="0 0 0" />
      <geometry>
        <mesh filename="$(find spider_description)/meshes/visual/LL4_tibia.STL" />
      </geometry>
      <material name="">
        <color rgba="0.752941176470588 0.752941176470588 0.752941176470588 1" />
      </material>
    </visual>
    <collision>
      <origin xyz="0 0 0" rpy="0 0 0" />
      <geometry>
        <mesh filename="$(find spider_description)/meshes/collision/LL4_tibia.STL" />
      </geometry>
    </collision>
  </link>
  <joint name="joint8_tibia" type="continuous">
    <origin xyz="-0.0549999999999999 0 0" rpy="0 -1.36202617641292 -2.53016856049393" />
    <parent link="LL4_fumer" />
    <child link="LL4_tibia" />
    <axis xyz="0.978286549337221 0 0.207256911551514" />
  </joint>
  <ros2_control name="LeggedSystemPositionOnly" type="system">
    <hardware>
      <plugin>gz_ros2_control/GazeboSimSystem</plugin>
    </hardware>

    <joint name="joint1_coxa">
      <command_interface name="position" />
      <state_interface name="position" />
      <state_interface name="velocity" />
    </joint>
    <joint name="joint1_fumer">
      <command_interface name="position" />
      <state_interface name="position" />
      <state_interface name="velocity" />
    </joint>
    <joint name="joint1_tibia">
      <command_interface name="position" />
      <state_interface name="position" />
      <state_interface name="velocity" />
    </joint>

    <joint name="joint2_coxa">
      <command_interface name="position" />
      <state_interface name="position" />
      <state_interface name="velocity" />
    </joint>
    <joint name="joint2_fumer">
      <command_interface name="position" />
      <state_interface name="position" />
      <state_interface name="velocity" />
    </joint>
    <joint name="joint2_tibia">
      <command_interface name="position" />
      <state_interface name="position" />
      <state_interface name="velocity" />
    </joint>

    <joint name="joint3_coxa">
      <command_interface name="position" />
      <state_interface name="position" />
      <state_interface name="velocity" />
    </joint>
    <joint name="joint3_fumer">
      <command_interface name="position" />
      <state_interface name="position" />
      <state_interface name="velocity" />
    </joint>
    <joint name="joint3_tibia">
      <command_interface name="position" />
      <state_interface name="position" />
      <state_interface name="velocity" />
    </joint>

    <joint name="joint4_coxa">
      <command_interface name="position" />
      <state_interface name="position" />
      <state_interface name="velocity" />
    </joint>
    <joint name="joint4_fumer">
      <command_interface name="position" />
      <state_interface name="position" />
      <state_interface name="velocity" />
    </joint>
    <joint name="joint4_tibia">
      <command_interface name="position" />
      <state_interface name="position" />
      <state_interface name="velocity" />
    </joint>

    <joint name="joint5_coxa">
      <command_interface name="position" />
      <state_interface name="position" />
      <state_interface name="velocity" />
    </joint>
    <joint name="joint5_fumer">
      <command_interface name="position" />
      <state_interface name="position" />
      <state_interface name="velocity" />
    </joint>
    <joint name="joint5_tibia">
      <command_interface name="position" />
      <state_interface name="position" />
      <state_interface name="velocity" />
    </joint>

    <joint name="joint6_coxa">
      <command_interface name="position" />
      <state_interface name="position" />
      <state_interface name="velocity" />
    </joint>
    <joint name="joint6_fumer">
      <command_interface name="position" />
      <state_interface name="position" />
      <state_interface name="velocity" />
    </joint>
    <joint name="joint6_tibia">
      <command_interface name="position" />
      <state_interface name="position" />
      <state_interface name="velocity" />
    </joint>

    <joint name="joint7_coxa">
      <command_interface name="position" />
      <state_interface name="position" />
      <state_interface name="velocity" />
    </joint>
    <joint name="joint7_fumer">
      <command_interface name="position" />
      <state_interface name="position" />
      <state_interface name="velocity" />
    </joint>
    <joint name="joint7_tibia">
      <command_interface name="position" />
      <state_interface name="position" />
      <state_interface name="velocity" />
    </joint>

    <joint name="joint8_coxa">
      <command_interface name="position" />
      <state_interface name="position" />
      <state_interface name="velocity" />
    </joint>
    <joint name="joint8_fumer">
      <command_interface name="position" />
      <state_interface name="position" />
      <state_interface name="velocity" />
    </joint>
    <joint name="joint8_tibia">
      <command_interface name="position" />
      <state_interface name="position" />
      <state_interface name="velocity" />
    </joint>
  </ros2_control>
  <!-- ############ GAZEBO ROS2 CONTROL PLUGIN ############ -->
  <gazebo>
    <plugin name="ign_ros2_control::IgnitionROS2ControlPlugin" filename="libgz_ros2_control-system.so">
      <parameters>
      $(find spider_description)/config/controller.yaml
      </parameters>
      <parameters>
      $(find spider_description)/config/gaz_ros2_ctl_use_sim.yaml
      </parameters>
    </plugin>
  </gazebo>

</robot>