<robot name="spider_description">
  <link name="dummy_base" />

  <joint name="dummy_base_to_base_link" type="fixed">
    <parent link="dummy_base" />
    <child link="base_link" />
    <origin xyz="0 0 0" rpy="0 0 0" />
  </joint>
  <link name="base_link">
    <inertial>
      <origin xyz="0.0419124697856288 0.0129912705123136 -0.00194512919498489" rpy="0 0 0" />
      <mass value="0.206593361987693" />
      <inertia ixx="0.000100835459421752" ixy="3.3190326442876E-07" ixz="6.85143109069958E-05" iyy="0.000699628428109392" iyz="-7.47632670675628E-08" izz="0.000612159753876248" />
    </inertial>
    <visual>
      <origin xyz="0 0 0" rpy="0 0 0" />
      <geometry>
        <mesh filename="file://$(find spider_description)/meshes/visual/base_link.STL" />
      </geometry>
      <material name="">
        <color rgba="0.752941176470588 0.752941176470588 0.752941176470588 1" />
      </material>
    </visual>
    <collision>
      <origin xyz="0 0 0" rpy="0 0 0" />
      <geometry>
        <mesh filename="file://$(find spider_description)/meshes/collision/base_link.STL" />
      </geometry>
    </collision>
  </link>
  <link name="RL1_coxa">
    <inertial>
      <origin xyz="-0.00349163991648843 0.0172300072694273 0.024439051068252" rpy="0 0 0" />
      <mass value="0.0118214563639757" />
      <inertia ixx="1.54720113656629E-06" ixy="-3.57556957341545E-08" ixz="-4.0276165283765E-08" iyy="1.03828170219183E-06" iyz="-8.80235914490984E-10" izz="1.47258336300693E-06" />
    </inertial>
    <visual>
      <origin xyz="0 0 0" rpy="0 0 0" />
      <geometry>
        <mesh filename="file://$(find spider_description)/meshes/visual/RL1_coxa.STL" />
      </geometry>
      <material name="">
        <color rgba="0.752941176470588 0.752941176470588 0.752941176470588 1" />
      </material>
    </visual>
    <collision>
      <origin xyz="0 0 0" rpy="0 0 0" />
      <geometry>
        <mesh filename="file://$(find spider_description)/meshes/collision/RL1_coxa.STL" />
      </geometry>
    </collision>
  </link>
  <joint name="joint1_coxa" type="continuous">
    <origin xyz="0.143023923046985 -0.028827601978856 0.00180390069504784" rpy="1.5707963267949 0 0.456646809528589" />
    <parent link="base_link" />
    <child link="RL1_coxa" />
    <axis xyz="0 1 0" />
  </joint>
  <link name="RL1_fumer">
    <inertial>
      <origin xyz="-0.0264233888332986 6.93889390390723E-18 -0.00234030420177805" rpy="0 0 0" />
      <mass value="0.00732061922605988" />
      <inertia ixx="1.66034801156124E-06" ixy="1.00585162486448E-21" ixz="-1.49987503139991E-09" iyy="3.33489508651991E-06" iyz="1.04555629426703E-21" izz="1.85153973126671E-06" />
    </inertial>
    <visual>
      <origin xyz="0 0 0" rpy="0 0 0" />
      <geometry>
        <mesh filename="file://$(find spider_description)/meshes/visual/RL1_fumer.STL" />
      </geometry>
      <material name="">
        <color rgba="1 1 1 1" />
      </material>
    </visual>
    <collision>
      <origin xyz="0 0 0" rpy="0 0 0" />
      <geometry>
        <mesh filename="file://$(find spider_description)/meshes/collision/RL1_fumer.STL" />
      </geometry>
    </collision>
  </link>
  <joint name="joint1_fumer" type="continuous">
    <origin xyz="-0.00591979008225604 0.0221000000000001 0.026855280400361" rpy="-2.03537963970565 1.06963032129347 1.15667679281028" />
    <parent link="RL1_coxa" />
    <child link="RL1_fumer" />
    <axis xyz="0 0 1" />
  </joint>
  <link name="RL1_tibia">
    <inertial>
      <origin xyz="0.00260154719028149 -0.013097537565338 0.000727426101389261" rpy="0 0 0" />
      <mass value="0.0131238915671885" />
      <inertia ixx="4.22996621859555E-06" ixy="1.19149405996142E-07" ixz="-1.17548949137053E-08" iyy="7.82194141970863E-07" iyz="-2.83284562385563E-07" izz="4.4245594105805E-06" />
    </inertial>
    <visual>
      <origin xyz="0 0 0" rpy="0 0 0" />
      <geometry>
        <mesh filename="file://$(find spider_description)/meshes/visual/RL1_tibia.STL" />
      </geometry>
      <material name="">
        <color rgba="0.752941176470588 0.752941176470588 0.752941176470588 1" />
      </material>
    </visual>
    <collision>
      <origin xyz="0 0 0" rpy="0 0 0" />
      <geometry>
        <mesh filename="file://$(find spider_description)/meshes/collision/RL1_tibia.STL" />
      </geometry>
    </collision>
  </link>
  <joint name="joint1_tibia" type="continuous">
    <origin xyz="-0.055 0 0" rpy="3.14159265358979 1.35383304701328 0.455416754848752" />
    <parent link="RL1_fumer" />
    <child link="RL1_tibia" />
    <axis xyz="0.976555650922224 0 0.215265093900221" />
  </joint>
  <link name="RL2_coxa">
    <inertial>
      <origin xyz="-0.00137410359807341 0.0172300072704422 0.0246489473554496" rpy="0 0 0" />
      <mass value="0.0118214563661804" />
      <inertia ixx="1.53973680405956E-06" ixy="-3.56986723887601E-08" ixz="-4.6080637183373E-08" iyy="1.0382817023383E-06" iyz="2.2021308274049E-09" izz="1.4800476962292E-06" />
    </inertial>
    <visual>
      <origin xyz="0 0 0" rpy="0 0 0" />
      <geometry>
        <mesh filename="file://$(find spider_description)/meshes/visual/RL2_coxa.STL" />
      </geometry>
      <material name="">
        <color rgba="0.752941176470588 0.752941176470588 0.752941176470588 1" />
      </material>
    </visual>
    <collision>
      <origin xyz="0 0 0" rpy="0 0 0" />
      <geometry>
        <mesh filename="file://$(find spider_description)/meshes/collision/RL2_coxa.STL" />
      </geometry>
    </collision>
  </link>
  <joint name="joint2_coxa" type="continuous">
    <origin xyz="0.0830253362173002 -0.0366006051591393 0.00180390069504788" rpy="1.5707963267949 0 0.371215936961481" />
    <parent link="base_link" />
    <child link="RL2_coxa" />
    <axis xyz="0 1 0" />
  </joint>
  <link name="RL2_fumer">
    <inertial>
      <origin xyz="-0.0264233888332985 0 -0.00234030420177726" rpy="0 0 0" />
      <mass value="0.00732061922605988" />
      <inertia ixx="1.66034801156124E-06" ixy="3.70576914423756E-22" ixz="-1.49987503139454E-09" iyy="3.33489508651991E-06" iyz="-2.5146290621612E-22" izz="1.85153973126671E-06" />
    </inertial>
    <visual>
      <origin xyz="0 0 0" rpy="0 0 0" />
      <geometry>
        <mesh filename="file://$(find spider_description)/meshes/visual/RL2_fumer.STL" />
      </geometry>
      <material name="">
        <color rgba="1 1 1 1" />
      </material>
    </visual>
    <collision>
      <origin xyz="0 0 0" rpy="0 0 0" />
      <geometry>
        <mesh filename="file://$(find spider_description)/meshes/collision/RL2_fumer.STL" />
      </geometry>
    </collision>
  </link>
  <joint name="joint2_fumer" type="continuous">
    <origin xyz="-0.00358516044020296 0.0220999999999999 0.0272653007432159" rpy="-1.84005724604345 1.0586197588623 1.33473036772911" />
    <parent link="RL2_coxa" />
    <child link="RL2_fumer" />
    <axis xyz="0 0 1" />
  </joint>
  <link name="RL2_tibia">
    <inertial>
      <origin xyz="0.00373414734956586 -0.0130839594099826 0.00111120240408577" rpy="0 0 0" />
      <mass value="0.0131238915536145" />
      <inertia ixx="4.23019149640981E-06" ixy="7.84253770640042E-08" ixz="1.01978479704144E-09" iyy="7.6533847696787E-07" iyz="-1.63714108486507E-07" izz="4.44118979210614E-06" />
    </inertial>
    <visual>
      <origin xyz="0 0 0" rpy="0 0 0" />
      <geometry>
        <mesh filename="file://$(find spider_description)/meshes/visual/RL2_tibia.STL" />
      </geometry>
      <material name="">
        <color rgba="0.752941176470588 0.752941176470588 0.752941176470588 1" />
      </material>
    </visual>
    <collision>
      <origin xyz="0 0 0" rpy="0 0 0" />
      <geometry>
        <mesh filename="file://$(find spider_description)/meshes/collision/RL2_tibia.STL" />
      </geometry>
    </collision>
  </link>
  <joint name="joint2_tibia" type="continuous">
    <origin xyz="-0.055 0 0" rpy="-3.14159265358979 1.4400547052635 0.436973540292822" />
    <parent link="RL2_fumer" />
    <child link="RL2_tibia" />
    <axis xyz="0.991465481571485 0 0.130369470552824" />
  </joint>
  <link name="RL3_coxa">
    <inertial>
      <origin xyz="0.00349358017075859 0.01723000702548 0.0244387737829021" rpy="0 0 0" />
      <mass value="0.0118214556819711" />
      <inertia ixx="1.51968692035686E-06" ixy="-3.45709549158988E-08" ixz="-5.40202304528258E-08" iyy="1.03828165876939E-06" iyz="9.17031077224167E-09" izz="1.50009735512406E-06" />
    </inertial>
    <visual>
      <origin xyz="0 0 0" rpy="0 0 0" />
      <geometry>
        <mesh filename="file://$(find spider_description)/meshes/visual/RL3_coxa.STL" />
      </geometry>
      <material name="">
        <color rgba="0.752941176470588 0.752941176470588 0.752941176470588 1" />
      </material>
    </visual>
    <collision>
      <origin xyz="0 0 0" rpy="0 0 0" />
      <geometry>
        <mesh filename="file://$(find spider_description)/meshes/collision/RL3_coxa.STL" />
      </geometry>
    </collision>
  </link>
  <joint name="joint3_coxa" type="continuous">
    <origin xyz="0.0230267493876147 -0.0443736083394228 0.00180390069504786" rpy="1.5707963267949 0 0.115999004572643" />
    <parent link="base_link" />
    <child link="RL3_coxa" />
    <axis xyz="0 1 0" />
  </joint>
  <link name="RL3_fumer">
    <inertial>
      <origin xyz="-0.0190060888231168 -0.0093450118645113 -0.00493699671842929" rpy="0 0 0" />
      <mass value="0.00732061922605988" />
      <inertia ixx="1.66034801156124E-06" ixy="-8.470329472543E-22" ixz="-1.4998750313965E-09" iyy="3.33489508651991E-06" iyz="-6.61744490042422E-23" izz="1.85153973126671E-06" />
    </inertial>
    <visual>
      <origin xyz="0 0 0" rpy="0 0 0" />
      <geometry>
        <mesh filename="file://$(find spider_description)/meshes/visual/RL3_fumer.STL" />
      </geometry>
      <material name="">
        <color rgba="1 1 1 1" />
      </material>
    </visual>
    <collision>
      <origin xyz="0 0 0" rpy="0 0 0" />
      <geometry>
        <mesh filename="file://$(find spider_description)/meshes/collision/RL3_fumer.STL" />
      </geometry>
    </collision>
  </link>
  <joint name="joint3_fumer" type="continuous">
    <origin xyz="-0.000624989213601535 0.0103198993706474 0.0294985850073072" rpy="-1.43474773528477 1.05506840370706 1.68932703577979" />
    <parent link="RL3_coxa" />
    <child link="RL3_fumer" />
    <axis xyz="0 0 1" />
  </joint>
  <link name="RL3_tibia">
    <inertial>
      <origin xyz="0.00531436167769063 -0.0130894520266102 0.000128909648472023" rpy="0 0 0" />
      <mass value="0.013123891554142" />
      <inertia ixx="4.23878064857726E-06" ixy="4.20082179122996E-08" ixz="4.18757972044376E-08" iyy="7.69154455506806E-07" iyz="-2.12494162555612E-07" izz="4.42878466326275E-06" />
    </inertial>
    <visual>
      <origin xyz="0 0 0" rpy="0 0 0" />
      <geometry>
        <mesh filename="file://$(find spider_description)/meshes/visual/RL3_tibia.STL" />
      </geometry>
      <material name="">
        <color rgba="0.752941176470588 0.752941176470588 0.752941176470588 1" />
      </material>
    </visual>
    <collision>
      <origin xyz="0 0 0" rpy="0 0 0" />
      <geometry>
        <mesh filename="file://$(find spider_description)/meshes/collision/RL3_tibia.STL" />
      </geometry>
    </collision>
  </link>
  <joint name="joint3_tibia" type="continuous">
    <origin xyz="-0.0475826999898183 -0.0093450118645113 0" rpy="0 1.50385829483433 -2.6917648290032" />
    <parent link="RL3_fumer" />
    <child link="RL3_tibia" />
    <axis xyz="0.997760486341758 0 -0.0668880549504796" />
  </joint>
  <link name="RL4_coxa">
    <inertial>
      <origin xyz="0.000221643431956145 0.0172339886263365 0.024773862822896" rpy="0 0 0" />
      <mass value="0.0118311142541974" />
      <inertia ixx="1.51589405750511E-06" ixy="3.36933854050161E-08" ixz="5.44221416465647E-08" iyy="1.03946598429508E-06" iyz="1.04056213225627E-08" izz="1.50574501931213E-06" />
    </inertial>
    <visual>
      <origin xyz="0 0 0" rpy="0 0 0" />
      <geometry>
        <mesh filename="file://$(find spider_description)/meshes/visual/RL4_coxa.STL" />
      </geometry>
      <material name="">
        <color rgba="0.752941176470588 0.752941176470588 0.752941176470588 1" />
      </material>
    </visual>
    <collision>
      <origin xyz="0 0 0" rpy="0 0 0" />
      <geometry>
        <mesh filename="file://$(find spider_description)/meshes/collision/RL4_coxa.STL" />
      </geometry>
    </collision>
  </link>
  <joint name="joint4_coxa" type="continuous">
    <origin xyz="-0.0369718374420689 -0.0521466115197065 0.00180390069504695" rpy="1.5707963267949 0 0.279272825129561" />
    <parent link="base_link" />
    <child link="RL4_coxa" />
    <axis xyz="0 1 0" />
  </joint>
  <link name="RL4_fumer">
    <inertial>
      <origin xyz="-0.0264233888332986 -1.38777878078145E-17 0.00455969579822089" rpy="0 0 0" />
      <mass value="0.00732061922605989" />
      <inertia ixx="1.66034801156124E-06" ixy="-1.11173074327127E-21" ixz="-1.49987503139615E-09" iyy="3.33489508651992E-06" iyz="-8.73502726855997E-22" izz="1.85153973126671E-06" />
    </inertial>
    <visual>
      <origin xyz="0 0 0" rpy="0 0 0" />
      <geometry>
        <mesh filename="file://$(find spider_description)/meshes/visual/RL4_fumer.STL" />
      </geometry>
      <material name="">
        <color rgba="1 1 1 1" />
      </material>
    </visual>
    <collision>
      <origin xyz="0 0 0" rpy="0 0 0" />
      <geometry>
        <mesh filename="file://$(find spider_description)/meshes/collision/RL4_fumer.STL" />
      </geometry>
    </collision>
  </link>
  <joint name="joint4_fumer" type="continuous">
    <origin xyz="-0.00289047043580869 0.0221000000000014 0.0273476723078892" rpy="1.34757833958992 1.0760490052699 1.37361152936902" />
    <parent link="RL4_coxa" />
    <child link="RL4_fumer" />
    <axis xyz="0 0 1" />
  </joint>
  <link name="RL4_tibia">
    <inertial>
      <origin xyz="0.0046194323285307 -0.0124119057556658 -0.00371988245181533" rpy="0 0 0" />
      <mass value="0.0131238915753325" />
      <inertia ixx="4.23942335586469E-06" ixy="1.02033759025192E-07" ixz="-4.08466826831512E-09" iyy="1.36774622353105E-06" iyz="-1.36758688276913E-06" izz="3.82955019670378E-06" />
    </inertial>
    <visual>
      <origin xyz="0 0 0" rpy="0 0 0" />
      <geometry>
        <mesh filename="file://$(find spider_description)/meshes/visual/RL4_tibia.STL" />
      </geometry>
      <material name="">
        <color rgba="0.752941176470588 0.752941176470588 0.752941176470588 1" />
      </material>
    </visual>
    <collision>
      <origin xyz="0 0 0" rpy="0 0 0" />
      <geometry>
        <mesh filename="file://$(find spider_description)/meshes/collision/RL4_tibia.STL" />
      </geometry>
    </collision>
  </link>
  <joint name="joint4_tibia" type="continuous">
    <origin xyz="-0.0550000000000001 0 0" rpy="0 -1.4654938088774 -0.809353512947539" />
    <parent link="RL4_fumer" />
    <child link="RL4_tibia" />
    <axis xyz="0.994460811195995 0 0.105108015847522" />
  </joint>
  <link name="LL1_coxa">
    <inertial>
      <origin xyz="0.0170998824043466 0.0172339901017211 -0.017927284271033" rpy="0 0 0" />
      <mass value="0.0118311172441887" />
      <inertia ixx="1.45657003099262E-06" ixy="-1.69225042702206E-08" ixz="6.66881674443564E-09" iyy="1.03946612492756E-06" iyz="-3.09376104608946E-08" izz="1.5650694795515E-06" />
    </inertial>
    <visual>
      <origin xyz="0 0 0" rpy="0 0 0" />
      <geometry>
        <mesh filename="file://$(find spider_description)/meshes/visual/LL1_coxa.STL" />
      </geometry>
      <material name="">
        <color rgba="0.752941176470588 0.752941176470588 0.752941176470588 1" />
      </material>
    </visual>
    <collision>
      <origin xyz="0 0 0" rpy="0 0 0" />
      <geometry>
        <mesh filename="file://$(find spider_description)/meshes/collision/LL1_coxa.STL" />
      </geometry>
    </collision>
  </link>
  <joint name="joint5_coxa" type="continuous">
    <origin xyz="0.121433238114814 0.0561023239846096 0.00180390069504789" rpy="1.5707963267949 0 0.779171496523206" />
    <parent link="base_link" />
    <child link="LL1_coxa" />
    <axis xyz="0 1 0" />
  </joint>
  <link name="LL1_fumer">
    <inertial>
      <origin xyz="-0.0264233888332985 0 0.00455969579822237" rpy="0 0 0" />
      <mass value="0.00732061922605988" />
      <inertia ixx="1.66034801156124E-06" ixy="5.29395592033938E-22" ixz="-1.49987503139699E-09" iyy="3.33489508651991E-06" iyz="-4.2351647362715E-22" izz="1.85153973126671E-06" />
    </inertial>
    <visual>
      <origin xyz="0 0 0" rpy="0 0 0" />
      <geometry>
        <mesh filename="file://$(find spider_description)/meshes/visual/LL1_fumer.STL" />
      </geometry>
      <material name="">
        <color rgba="1 1 1 1" />
      </material>
    </visual>
    <collision>
      <origin xyz="0 0 0" rpy="0 0 0" />
      <geometry>
        <mesh filename="file://$(find spider_description)/meshes/collision/LL1_fumer.STL" />
      </geometry>
    </collision>
  </link>
  <joint name="joint5_fumer" type="continuous">
    <origin xyz="0.0211255891188228 0.0221 -0.0176056662578466" rpy="-2.73801909944616 -0.582101669425183 2.48122445090949" />
    <parent link="LL1_coxa" />
    <child link="LL1_fumer" />
    <axis xyz="0 0 1" />
  </joint>
  <link name="LL1_tibia">
    <inertial>
      <origin xyz="-0.00279894329842953 -0.0130976389443435 -0.00313843570289792" rpy="0 0 0" />
      <mass value="0.0131238945399001" />
      <inertia ixx="4.36602557276728E-06" ixy="-2.59110541265302E-07" ixz="-7.85276269962679E-08" iyy="7.97432719732035E-07" iyz="2.87128419374741E-07" izz="4.27326198471528E-06" />
    </inertial>
    <visual>
      <origin xyz="0 0 0" rpy="0 0 0" />
      <geometry>
        <mesh filename="file://$(find spider_description)/meshes/visual/LL1_tibia.STL" />
      </geometry>
      <material name="">
        <color rgba="0.752941176470588 0.752941176470588 0.752941176470588 1" />
      </material>
    </visual>
    <collision>
      <origin xyz="0 0 0" rpy="0 0 0" />
      <geometry>
        <mesh filename="file://$(find spider_description)/meshes/collision/LL1_tibia.STL" />
      </geometry>
    </collision>
  </link>
  <joint name="joint5_tibia" type="continuous">
    <origin xyz="-0.0549999999999999 0 0" rpy="-3.14159265358979 0.69476645340304 2.60363290009658" />
    <parent link="LL1_fumer" />
    <child link="LL1_tibia" />
    <axis xyz="0.640206045739845 0 0.768203240684489" />
  </joint>
  <link name="LL2_coxa">
    <inertial>
      <origin xyz="0.0127223100660754 0.0169176353715654 -0.0226841740829874" rpy="0 0 0" />
      <mass value="0.0118311161508981" />
      <inertia ixx="1.56088144680102E-06" ixy="-2.81600783319572E-08" ixz="2.19394756026617E-08" iyy="1.03946603017998E-06" iyz="-2.12253461630087E-08" izz="1.46075766684656E-06" />
    </inertial>
    <visual>
      <origin xyz="0 0 0" rpy="0 0 0" />
      <geometry>
        <mesh filename="file://$(find spider_description)/meshes/visual/LL2_coxa.STL" />
      </geometry>
      <material name="">
        <color rgba="0.752941176470588 0.752941176470588 0.752941176470588 1" />
      </material>
    </visual>
    <collision>
      <origin xyz="0 0 0" rpy="0 0 0" />
      <geometry>
        <mesh filename="file://$(find spider_description)/meshes/collision/LL2_coxa.STL" />
      </geometry>
    </collision>
  </link>
  <joint name="joint6_coxa" type="continuous">
    <origin xyz="0.0614346512851298 0.0483293208043272 0.00180390069504796" rpy="1.5707963267949 0 0.799360343333685" />
    <parent link="base_link" />
    <child link="LL2_coxa" />
    <axis xyz="0 1 0" />
  </joint>
  <link name="LL2_fumer">
    <inertial>
      <origin xyz="-0.0264233888332986 0 0.0120596957982234" rpy="0 0 0" />
      <mass value="0.00732061922605988" />
      <inertia ixx="1.66034801156124E-06" ixy="1.05879118406788E-22" ixz="-1.49987503139611E-09" iyy="3.33489508651991E-06" iyz="5.09543257332665E-22" izz="1.85153973126671E-06" />
    </inertial>
    <visual>
      <origin xyz="0 0 0" rpy="0 0 0" />
      <geometry>
        <mesh filename="file://$(find spider_description)/meshes/visual/LL2_fumer.STL" />
      </geometry>
      <material name="">
        <color rgba="1 1 1 1" />
      </material>
    </visual>
    <collision>
      <origin xyz="0 0 0" rpy="0 0 0" />
      <geometry>
        <mesh filename="file://$(find spider_description)/meshes/collision/LL2_fumer.STL" />
      </geometry>
    </collision>
  </link>
  <joint name="joint6_fumer" type="continuous">
    <origin xyz="0.0204800515080549 0.0220999999999997 -0.0183525881070598" rpy="-2.71143718885399 -0.610479400867026 2.46663802210369" />
    <parent link="LL2_coxa" />
    <child link="LL2_fumer" />
    <axis xyz="0 0 1" />
  </joint>
  <link name="LL2_tibia">
    <inertial>
      <origin xyz="-0.00780217032358205 -0.01309839267037 -0.00872256326972962" rpy="0 0 0" />
      <mass value="0.0131238944675766" />
      <inertia ixx="4.36428717131208E-06" ixy="-2.17234269804496E-07" ixz="-8.58852825162038E-08" iyy="7.89056187070732E-07" iyz="2.6858651802412E-07" izz="4.28337690198118E-06" />
    </inertial>
    <visual>
      <origin xyz="0 0 0" rpy="0 0 0" />
      <geometry>
        <mesh filename="file://$(find spider_description)/meshes/visual/LL2_tibia.STL" />
      </geometry>
      <material name="">
        <color rgba="0.752941176470588 0.752941176470588 0.752941176470588 1" />
      </material>
    </visual>
    <collision>
      <origin xyz="0 0 0" rpy="0 0 0" />
      <geometry>
        <mesh filename="file://$(find spider_description)/meshes/collision/LL2_tibia.STL" />
      </geometry>
    </collision>
  </link>
  <joint name="joint6_tibia" type="continuous">
    <origin xyz="-0.055 0 0" rpy="3.14159265358979 0.730667432781409 2.63033642671627" />
    <parent link="LL2_fumer" />
    <child link="LL2_tibia" />
    <axis xyz="0.667366840256722 0 0.744729145747472" />
  </joint>
  <link name="LL3_coxa">
    <inertial>
      <origin xyz="0.0139602506469437 0.0172339889077581 -0.0204671641770284" rpy="0 0 0" />
      <mass value="0.0118311133553872" />
      <inertia ixx="1.46157125552418E-06" ixy="-2.17239736681064E-08" ixz="2.37095607651922E-08" iyy="1.0394659305145E-06" iyz="-2.77774755690175E-08" izz="1.56006751193327E-06" />
    </inertial>
    <visual>
      <origin xyz="0 0 0" rpy="0 0 0" />
      <geometry>
        <mesh filename="file://$(find spider_description)/meshes/visual/LL3_coxa.STL" />
      </geometry>
      <material name="">
        <color rgba="0.752941176470588 0.752941176470588 0.752941176470588 1" />
      </material>
    </visual>
    <collision>
      <origin xyz="0 0 0" rpy="0 0 0" />
      <geometry>
        <mesh filename="file://$(find spider_description)/meshes/collision/LL3_coxa.STL" />
      </geometry>
    </collision>
  </link>
  <joint name="joint7_coxa" type="continuous">
    <origin xyz="0.00143606445544368 0.0405563176240433 0.0018039006950479" rpy="1.5707963267949 0 0.762566282617874" />
    <parent link="base_link" />
    <child link="LL3_coxa" />
    <axis xyz="0 1 0" />
  </joint>
  <link name="LL3_fumer">
    <inertial>
      <origin xyz="-0.0264233888332985 -1.38777878078145E-17 0.00455969579822281" rpy="0 0 0" />
      <mass value="0.00732061922605988" />
      <inertia ixx="1.66034801156124E-06" ixy="-6.88214269644119E-22" ixz="-1.49987503139482E-09" iyy="3.3348950865199E-06" iyz="-2.64697796016969E-22" izz="1.85153973126671E-06" />
    </inertial>
    <visual>
      <origin xyz="0 0 0" rpy="0 0 0" />
      <geometry>
        <mesh filename="file://$(find spider_description)/meshes/visual/LL3_fumer.STL" />
      </geometry>
      <material name="">
        <color rgba="1 1 1 1" />
      </material>
    </visual>
    <collision>
      <origin xyz="0 0 0" rpy="0 0 0" />
      <geometry>
        <mesh filename="file://$(find spider_description)/meshes/collision/LL3_fumer.STL" />
      </geometry>
    </collision>
  </link>
  <joint name="joint7_fumer" type="continuous">
    <origin xyz="0.0179847256047489 0.0221 -0.0208038372643574" rpy="-2.66841470881931 -0.745546268941601 2.49508842776342" />
    <parent link="LL3_coxa" />
    <child link="LL3_fumer" />
    <axis xyz="0 0 1" />
  </joint>
  <link name="LL3_tibia">
    <inertial>
      <origin xyz="-0.00309435726524095 -0.00999543050929356 -0.00304937467236494" rpy="0 0 0" />
      <mass value="0.0211237959439876" />
      <inertia ixx="4.9950866400634E-06" ixy="-1.39393620012794E-07" ixz="-2.67338640754455E-07" iyy="1.32635281980292E-06" iyz="1.78140060908311E-07" izz="5.01286567504397E-06" />
    </inertial>
    <visual>
      <origin xyz="0 0 0" rpy="0 0 0" />
      <geometry>
        <mesh filename="file://$(find spider_description)/meshes/visual/LL3_tibia.STL" />
      </geometry>
      <material name="">
        <color rgba="0.752941176470588 0.752941176470588 0.752941176470588 1" />
      </material>
    </visual>
    <collision>
      <origin xyz="0 0 0" rpy="0 0 0" />
      <geometry>
        <mesh filename="file://$(find spider_description)/meshes/collision/LL3_tibia.STL" />
      </geometry>
    </collision>
  </link>
  <joint name="joint7_tibia" type="continuous">
    <origin xyz="-0.0549999999999996 0 0" rpy="-3.14159265358979 0.857949539202521 2.68310369735863" />
    <parent link="LL3_fumer" />
    <child link="LL3_tibia" />
    <axis xyz="0.756503173249345 0 0.65399002199091" />
  </joint>
  <link name="LL4_coxa">
    <inertial>
      <origin xyz="0.000589847914708751 0.0172300062160811 -0.0246801710520806" rpy="0 0 0" />
      <mass value="0.0118214537178174" />
      <inertia ixx="1.5367477651219E-06" ixy="3.56106725590858E-08" ixz="-4.78840582046048E-08" iyy="1.03828151740302E-06" iyz="-3.33597281018614E-09" izz="1.48303585401202E-06" />
    </inertial>
    <visual>
      <origin xyz="0 0 0" rpy="0 0 0" />
      <geometry>
        <mesh filename="file://$(find spider_description)/meshes/visual/LL4_coxa.STL" />
      </geometry>
      <material name="">
        <color rgba="0.752941176470588 0.752941176470588 0.752941176470588 1" />
      </material>
    </visual>
    <collision>
      <origin xyz="0 0 0" rpy="0 0 0" />
      <geometry>
        <mesh filename="file://$(find spider_description)/meshes/collision/LL4_coxa.STL" />
      </geometry>
    </collision>
  </link>
  <joint name="joint8_coxa" type="continuous">
    <origin xyz="-0.058562522374242 0.0327833144437591 0.00180390069504791" rpy="1.5707963267949 0 0.138794201888939" />
    <parent link="base_link" />
    <child link="LL4_coxa" />
    <axis xyz="0 1 0" />
  </joint>
  <link name="LL4_fumer">
    <inertial>
      <origin xyz="-0.0264233888332986 6.93889390390723E-18 -0.00234030420177728" rpy="0 0 0" />
      <mass value="0.00732061922605988" />
      <inertia ixx="1.66034801156124E-06" ixy="8.470329472543E-22" ixz="-1.49987503139453E-09" iyy="3.33489508651992E-06" iyz="-4.96308367531817E-23" izz="1.85153973126671E-06" />
    </inertial>
    <visual>
      <origin xyz="0 0 0" rpy="0 0 0" />
      <geometry>
        <mesh filename="file://$(find spider_description)/meshes/visual/LL4_fumer.STL" />
      </geometry>
      <material name="">
        <color rgba="1 1 1 1" />
      </material>
    </visual>
    <collision>
      <origin xyz="0 0 0" rpy="0 0 0" />
      <geometry>
        <mesh filename="file://$(find spider_description)/meshes/collision/LL4_fumer.STL" />
      </geometry>
    </collision>
  </link>
  <joint name="joint8_fumer" type="continuous">
    <origin xyz="0.00271661781563643 0.0220999999999999 -0.0273654889896707" rpy="1.33721860319905 -1.1298490006671 1.78272807584438" />
    <parent link="LL4_coxa" />
    <child link="LL4_fumer" />
    <axis xyz="0 0 1" />
  </joint>
  <link name="LL4_tibia">
    <inertial>
      <origin xyz="-0.00283536696605889 -0.0130639420547866 0.000369861511789499" rpy="0 0 0" />
      <mass value="0.0131238915939716" />
      <inertia ixx="4.22467226051278E-06" ixy="-1.76333801363491E-07" ixz="9.44080885180267E-09" iyy="8.58388936238902E-07" iyz="5.78334636597505E-07" izz="4.35365859002539E-06" />
    </inertial>
    <visual>
      <origin xyz="0 0 0" rpy="0 0 0" />
      <geometry>
        <mesh filename="file://$(find spider_description)/meshes/visual/LL4_tibia.STL" />
      </geometry>
      <material name="">
        <color rgba="0.752941176470588 0.752941176470588 0.752941176470588 1" />
      </material>
    </visual>
    <collision>
      <origin xyz="0 0 0" rpy="0 0 0" />
      <geometry>
        <mesh filename="file://$(find spider_description)/meshes/collision/LL4_tibia.STL" />
      </geometry>
    </collision>
  </link>
  <joint name="joint8_tibia" type="continuous">
    <origin xyz="-0.055 0 0" rpy="0 -1.36202617641292 -2.5823705934248" />
    <parent link="LL4_fumer" />
    <child link="LL4_tibia" />
    <axis xyz="0.978286549337221 0 0.207256911551514" />
  </joint>
  <ros2_control name="LeggedSystemPositionOnly" type="system">
    <hardware>
      <plugin>gz_ros2_control/GazeboSimSystem</plugin>
    </hardware>

    <joint name="joint1_coxa">
      <command_interface name="position" />
      <state_interface name="position" />
      <state_interface name="velocity" />
    </joint>
    <joint name="joint1_fumer">
      <command_interface name="position" />
      <state_interface name="position" />
      <state_interface name="velocity" />
    </joint>
    <joint name="joint1_tibia">
      <command_interface name="position" />
      <state_interface name="position" />
      <state_interface name="velocity" />
    </joint>

    <joint name="joint2_coxa">
      <command_interface name="position" />
      <state_interface name="position" />
      <state_interface name="velocity" />
    </joint>
    <joint name="joint2_fumer">
      <command_interface name="position" />
      <state_interface name="position" />
      <state_interface name="velocity" />
    </joint>
    <joint name="joint2_tibia">
      <command_interface name="position" />
      <state_interface name="position" />
      <state_interface name="velocity" />
    </joint>

    <joint name="joint3_coxa">
      <command_interface name="position" />
      <state_interface name="position" />
      <state_interface name="velocity" />
    </joint>
    <joint name="joint3_fumer">
      <command_interface name="position" />
      <state_interface name="position" />
      <state_interface name="velocity" />
    </joint>
    <joint name="joint3_tibia">
      <command_interface name="position" />
      <state_interface name="position" />
      <state_interface name="velocity" />
    </joint>

    <joint name="joint4_coxa">
      <command_interface name="position" />
      <state_interface name="position" />
      <state_interface name="velocity" />
    </joint>
    <joint name="joint4_fumer">
      <command_interface name="position" />
      <state_interface name="position" />
      <state_interface name="velocity" />
    </joint>
    <joint name="joint4_tibia">
      <command_interface name="position" />
      <state_interface name="position" />
      <state_interface name="velocity" />
    </joint>

    <joint name="joint5_coxa">
      <command_interface name="position" />
      <state_interface name="position" />
      <state_interface name="velocity" />
    </joint>
    <joint name="joint5_fumer">
      <command_interface name="position" />
      <state_interface name="position" />
      <state_interface name="velocity" />
    </joint>
    <joint name="joint5_tibia">
      <command_interface name="position" />
      <state_interface name="position" />
      <state_interface name="velocity" />
    </joint>

    <joint name="joint6_coxa">
      <command_interface name="position" />
      <state_interface name="position" />
      <state_interface name="velocity" />
    </joint>
    <joint name="joint6_fumer">
      <command_interface name="position" />
      <state_interface name="position" />
      <state_interface name="velocity" />
    </joint>
    <joint name="joint6_tibia">
      <command_interface name="position" />
      <state_interface name="position" />
      <state_interface name="velocity" />
    </joint>

    <joint name="joint7_coxa">
      <command_interface name="position" />
      <state_interface name="position" />
      <state_interface name="velocity" />
    </joint>
    <joint name="joint7_fumer">
      <command_interface name="position" />
      <state_interface name="position" />
      <state_interface name="velocity" />
    </joint>
    <joint name="joint7_tibia">
      <command_interface name="position" />
      <state_interface name="position" />
      <state_interface name="velocity" />
    </joint>

    <joint name="joint8_coxa">
      <command_interface name="position" />
      <state_interface name="position" />
      <state_interface name="velocity" />
    </joint>
    <joint name="joint8_fumer">
      <command_interface name="position" />
      <state_interface name="position" />
      <state_interface name="velocity" />
    </joint>
    <joint name="joint8_tibia">
      <command_interface name="position" />
      <state_interface name="position" />
      <state_interface name="velocity" />
    </joint>
  </ros2_control>
  <!-- ############ GAZEBO ROS2 CONTROL PLUGIN ############ -->
  <gazebo>
    <plugin name="ign_ros2_control::IgnitionROS2ControlPlugin" filename="libgz_ros2_control-system.so">
      <parameters>
      $(find spider_description)/config/controller.yaml
      </parameters>
    </plugin>
  </gazebo>

</robot>